<?xml version="1.0"?>
<robot xmlns:xacro="http://ros.org/wiki/xacro">

  <xacro:arg name="type" default="rg2" />
  <xacro:include filename="$(find onrobot_description)/urdf/inc/rg_common.xacro" />

  <xacro:macro name="inner_knuckle_joint" params="prefix fingerprefix reflect">
    <joint name="${prefix}${fingerprefix}_inner_knuckle_joint" type="revolute">
      <origin xyz="0 ${reflect * -0.007678} 0.1422970" rpy="0 0 ${(reflect - 1) * pi / 2}" />
      <parent link="${prefix}onrobot_base_link" />
      <child link="${prefix}${fingerprefix}_inner_knuckle" />
      <axis xyz="1 0 0" />
      <limit lower="-0.785398" upper="0.785398" velocity="100.0" effort="1000" />
      <mimic joint="${prefix}finger_joint" multiplier="-1" offset="0" />
    </joint>
  </xacro:macro>

  <xacro:macro name="inner_finger_joint" params="prefix fingerprefix">
    <joint name="${prefix}${fingerprefix}_inner_finger_joint" type="revolute">
      <origin xyz="0 ${-(0.056770-0.017178)} ${0.163974-0.125797}" rpy="0 0 0" />
      <parent link="${prefix}${fingerprefix}_outer_knuckle" />
      <child link="${prefix}${fingerprefix}_inner_finger" />
      <axis xyz="1 0 0" />
      <limit lower="-0.872665" upper="0.872665" velocity="100.0" effort="1000" />
      <mimic joint="${prefix}finger_joint" multiplier="1" offset="0" />
    </joint>
  </xacro:macro>
  
  <xacro:macro name="finger_joint" params="prefix">
    <joint name="${prefix}finger_joint" type="revolute">
      <origin xyz="0 -0.017178 0.125797" rpy="0 0 0" />
      <parent link="${prefix}onrobot_base_link" />
      <child link="${prefix}left_outer_knuckle" />
      <axis xyz="-1 0 0" />
      <limit lower="-0.558505" upper="0.785398" velocity="100.0" effort="1000" />
      <mimic joint="${prefix}finger_width" multiplier="${0.85 * ((-0.558505 - 0.785398) / 0.110)}" offset="0.785398" />
    </joint>
    <xacro:finger_joints prefix="${prefix}" fingerprefix="left" reflect="1.0"/>
  </xacro:macro>

  <xacro:macro name="right_outer_knuckle_joint" params="prefix">
    <joint name="${prefix}right_outer_knuckle_joint" type="revolute">
      <origin xyz="0 0.017178 0.125797" rpy="0 0 ${pi}" />
      <parent link="${prefix}onrobot_base_link" />
      <child link="${prefix}right_outer_knuckle" />
      <axis xyz="1 0 0" />
      <limit lower="-0.785398" upper="0.785398" velocity="100.0" effort="1000" />
      <mimic joint="${prefix}finger_joint" multiplier="-1" offset="0" />
    </joint>
    <xacro:finger_joints prefix="${prefix}" fingerprefix="right" reflect="-1.0"/>
  </xacro:macro>

  <xacro:macro name="finger_tips" params="prefix">
    <link name="${prefix}left_finger_tip"/>
    <link name="${prefix}right_finger_tip"/>
    <link name="${prefix}gripper_tcp"/>

    <joint name="${prefix}left_finger_tip_joint" type="fixed">
      <origin xyz="0 0.019 0.038" rpy="0 0 0" />
      <parent link="${prefix}left_inner_finger" />
      <child link="${prefix}left_finger_tip" />
    </joint>

    <joint name="${prefix}finger_width" type="prismatic">
      <origin xyz="0 0 0" rpy="${pi} 0 0" />
      <parent link="${prefix}left_finger_tip" />
      <child link="${prefix}right_finger_tip" />
      <axis xyz="0 -1 0" />
      <limit lower="0" upper="0.110" velocity="0.127" effort="40" />
    </joint>

    <joint name="${prefix}tcp_joint" type="fixed">
      <origin xyz="0 0 0.218" rpy="0 0 0" />
      <parent link="${prefix}onrobot_base_link" />
      <child link="${prefix}gripper_tcp" />
    </joint>
  </xacro:macro>

  <xacro:macro name="onrobot_rg2" params="prefix">
    <xacro:onrobot_base_link prefix="${prefix}" />
    <xacro:finger_links prefix="${prefix}" fingerprefix="left"/>
    <xacro:finger_links prefix="${prefix}" fingerprefix="right"/>
    <xacro:finger_joint prefix="${prefix}"/>
    <xacro:finger_tips prefix="${prefix}"/>
    <xacro:right_outer_knuckle_joint prefix="${prefix}"/>
    <xacro:transmission_macro prefix="${prefix}" joint_name="finger_width"/>
  </xacro:macro>
</robot>